Workbook

Sheet Ingredient Database
A1: Kitchen Share — Ingredient Nutrition Database
A2: All values per 100 g unless noted. Add new ingredients as rows — recipe sheets look them up by exact name.
A4: Ingredient | B4: Basis | C4: Calories | D4: Protein (g) | E4: Carbs (g) | F4: Fat (g) | G4: Fiber (g) | H4: Iron (mg) | I4: Calcium (mg) | J4: Magnesium (mg) | K4: Potassium (mg) | L4: Zinc (mg) | M4: Vitamin A (mcg) | N4: Vitamin C (mg) | O4: Folate (mcg)
A5: Barley, cooked | B5: 100 g | C5: 123 | D5: 2.3 | E5: 28.2 | F5: 0.4 | G5: 3.8 | H5: 1.3 | I5: 11 | J5: 22 | K5: 93 | L5: 1.3 | M5: 0 | N5: 0 | O5: 16
A6: Jasmine rice, cooked | B6: 100 g | C6: 130 | D6: 2.7 | E6: 28 | F6: 0.3 | G6: 0.4 | H6: 1.2 | I6: 3 | J6: 12 | K6: 35 | L6: 0.5 | M6: 0 | N6: 0 | O6: 45
A7: Parboiled rice, cooked | B7: 100 g | C7: 123 | D7: 2.6 | E7: 26 | F7: 0.2 | G7: 0.4 | H7: 0.5 | I7: 3 | J7: 15 | K7: 45 | L7: 0.5 | M7: 0 | N7: 0 | O7: 20
A8: Chickpeas, cooked | B8: 100 g | C8: 164 | D8: 8.9 | E8: 27.4 | F8: 2.6 | G8: 7.6 | H8: 2.9 | I8: 49 | J8: 48 | K8: 291 | L8: 1.5 | M8: 1 | N8: 1.3 | O8: 172
A9: Green peas | B9: 100 g | C9: 81 | D9: 5.4 | E9: 14.5 | F9: 0.4 | G9: 5.7 | H9: 1.5 | I9: 25 | J9: 33 | K9: 244 | L9: 1.2 | M9: 38 | N9: 40 | O9: 65
A10: Black lentils, dry curry style (garlic, onion, turmeric, cumin, chile) | B10: 100 g | C10: 167 | D10: 13 | E10: 25 | F10: 1.5 | G10: 8 | H10: 4.72 | I10: 25 | J10: 45 | K10: 370 | L10: 2 | M10: 0 | N10: 2 | O10: 180
A11: Tomato-onion-garlic-ginger-curry leaf base | B11: 100 g | C11: 40 | D11: 1.5 | E11: 8 | F11: 0.3 | G11: 1.5 | H11: 0.5 | I11: 15 | J11: 10 | K11: 220 | L11: 0.2 | M11: 20 | N11: 10 | O11: 15
A12: Extra virgin olive oil | B12: 100 g | C12: 884 | D12: 0 | E12: 0 | F12: 100 | G12: 0 | H12: 0 | I12: 0 | J12: 0 | K12: 0 | L12: 0 | M12: 0 | N12: 0 | O12: 0
A13: Vegetable oil, neutral | B13: 100 g | C13: 884 | D13: 0 | E13: 0 | F13: 100 | G13: 0 | H13: 0 | I13: 0 | J13: 0 | K13: 0 | L13: 0 | M13: 0 | N13: 0 | O13: 0
A14: Garlic clove | B14: 1 clove (~3 g) | C14: 4.5 | D14: 0.19 | E14: 1 | F14: 0.02 | G14: 0 | H14: 0.05 | I14: 5 | J14: 0 | K14: 12 | L14: 0 | M14: 0 | N14: 0 | O14: 0
A15: Chickwheat seitan (Avocados & Ales base recipe) | B15: 100 g | C15: 165 | D15: 26 | E15: 4 | F15: 4 | G15: 1 | H15: 3.5 | I15: 20 | J15: 25 | K15: 90 | L15: 1.2 | M15: 0 | N15: 0 | O15: 5
A16: La Banderita super burrito flour tortilla | B16: 100 g | C16: 333 | D16: 8.9 | E16: 56 | F16: 7.8 | G16: 2.5 | H16: 2.6 | I16: 80 | J16: 20 | K16: 100 | L16: 0.6 | M16: 0 | N16: 0 | O16: 100
... A38: Flax meal | B38: 100 g | C38: 534 | D38: 18.3 | E38: 28.9 | F38: 42.2 | G38: 27.3 | H38: 5.7 | I38: 255 | J38: 392 | K38: 813 | L38: 4.3 | M38: 0 | N38: 0 | O38: 0

Sheet Recipe - Banh Mi Bowl
A1: Banh Mi Grain Bowl
A2: Per jar / per serving — pulls nutrient values live from 'Ingredient Database'
A4: Ingredient (must match database exactly) | B4: Amount (g, or units) | C4: Multiplier (x /100g) | D4: Calories | E4: Protein (g) | F4: Carbs (g) | G4: Fat (g) | H4: Fiber (g) | I4: Iron (mg) | J4: Calcium (mg) | K4: Magnesium (mg) | L4: Potassium (mg) | M4: Zinc (mg) | N4: Vitamin A (mcg) | O4: Vitamin C (mg) | P4: Folate (mcg)
A5: Barley, cooked | B5: 100 g | C5: 1 | D5: =IFERROR(INDEX('Ingredient Database'!$C$5:$C$38,MATCH($A5,'Ingredient Database'!$A$5:$A$38,0))*$C5,"check name") -> 123 | E5: =IFERROR(INDEX('Ingredient Database'!$D$5:$D$38,MATCH($A5,'Ingredient Database'!$A$5:$A$38,0))*$C5,"check name") -> 2.3 | F5: =IFERROR(INDEX('Ingredient Database'!$E$5:$E$38,MATCH($A5,'Ingredient Database'!$A$5:$A$38,0))*$C5,"check name") -> 28.2 | G5: =IFERROR(INDEX('Ingredient Database'!$F$5:$F$38,MATCH($A5,'Ingredient Database'!$A$5:$A$38,0))*$C5,"check name") -> 0.4 | H5: =IFERROR(INDEX('Ingredient Database'!$G$5:$G$38,MATCH($A5,'Ingredient Database'!$A$5:$A$38,0))*$C5,"check name") -> 3.8 | I5: =IFERROR(INDEX('Ingredient Database'!$H$5:$H$38,MATCH($A5,'Ingredient Database'!$A$5:$A$38,0))*$C5,"check name") -> 1.3 | J5: =IFERROR(INDEX('Ingredient Database'!$I$5:$I$38,MATCH($A5,'Ingredient Database'!$A$5:$A$38,0))*$C5,"check name") -> 11 | K5: =IFERROR(INDEX('Ingredient Database'!$J$5:$J$38,MATCH($A5,'Ingredient Database'!$A$5:$A$38,0))*$C5,"check name") -> 22 | L5: =IFERROR(INDEX('Ingredient Database'!$K$5:$K$38,MATCH($A5,'Ingredient Database'!$A$5:$A$38,0))*$C5,"check name") -> 93 | M5: =IFERROR(INDEX('Ingredient Database'!$L$5:$L$38,MATCH($A5,'Ingredient Database'!$A$5:$A$38,0))*$C5,"check name") -> 1.3 | N5: =IFERROR(INDEX('Ingredient Database'!$M$5:$M$38,MATCH($A5,'Ingredient Database'!$A$5:$A$38,0))*$C5,"check name") -> 0 | O5: =IFERROR(INDEX('Ingredient Database'!$N$5:$N$38,MATCH($A5,'Ingredient Database'!$A$5:$A$38,0))*$C5,"check name") -> 0 | P5: =IFERROR(INDEX('Ingredient Database'!$O$5:$O$38,MATCH($A5,'Ingredient Database'!$A$5:$A$38,0))*$C5,"check name") -> 16
A6: Creamy avocado dressing (lime, mayo/coconut milk, fish sauce, agave) | B6: 85 g | C6: 0.85 | D6: =IFERROR(INDEX('Ingredient Database'!$C$5:$C$38,MATCH($A6,'Ingredient Database'!$A$5:$A$38,0))*$C6,"check name") -> 140.25 | E6: =IFERROR(INDEX('Ingredient Database'!$D$5:$D$38,MATCH($A6,'Ingredient Database'!$A$5:$A$38,0))*$C6,"check name") -> 1.53 | F6: =IFERROR(INDEX('Ingredient Database'!$E$5:$E$38,MATCH($A6,'Ingredient Database'!$A$5:$A$38,0))*$C6,"check name") -> 6.97 | G6: =IFERROR(INDEX('Ingredient Database'!$F$5:$F$38,MATCH($A6,'Ingredient Database'!$A$5:$A$38,0))*$C6,"check name") -> 13.005 | H6: =IFERROR(INDEX('Ingredient Database'!$G$5:$G$38,MATCH($A6,'Ingredient Database'!$A$5:$A$38,0))*$C6,"check name") -> 2.975 | I6: =IFERROR(INDEX('Ingredient Database'!$H$5:$H$38,MATCH($A6,'Ingredient Database'!$A$5:$A$38,0))*$C6,"check name") -> 0.51 | J6: =IFERROR(INDEX('Ingredient Database'!$I$5:$I$38,MATCH($A6,'Ingredient Database'!$A$5:$A$38,0))*$C6,"check name") -> 12.75 | K6: =IFERROR(INDEX('Ingredient Database'!$J$5:$J$38,MATCH($A6,'Ingredient Database'!$A$5:$A$38,0))*$C6,"check name") -> 17 | L6: =IFERROR(INDEX('Ingredient Database'!$K$5:$K$38,MATCH($A6,'Ingredient Database'!$A$5:$A$38,0))*$C6,"check name") -> 246.5 | M6: =IFERROR(INDEX('Ingredient Database'!$L$5:$L$38,MATCH($A6,'Ingredient Database'!$A$5:$A$38,0))*$C6,"check name") -> 0.425 | N6: =IFERROR(INDEX('Ingredient Database'!$M$5:$M$38,MATCH($A6,'Ingredient Database'!$A$5:$A$38,0))*$C6,"check name") -> 51 | O6: =IFERROR(INDEX('Ingredient Database'!$N$5:$N$38,MATCH($A6,'Ingredient Database'!$A$5:$A$38,0))*$C6,"check name") -> 5.95 | P6: =IFERROR(INDEX('Ingredient Database'!$O$5:$O$38,MATCH($A6,'Ingredient Database'!$A$5:$A$38,0))*$C6,"check name") -> 15.3
A7: Firm tofu (Pulmuone) | B7: 90.7 g | C7: 0.907 | D7: =IFERROR(INDEX('Ingredient Database'!$C$5:$C$38,MATCH($A7,'Ingredient Database'!$A$5:$A$38,0))*$C7,"check name") -> 129.701 | E7: =IFERROR(INDEX('Ingredient Database'!$D$5:$D$38,MATCH($A7,'Ingredient Database'!$A$5:$A$38,0))*$C7,"check name") -> 14.0585 | F7: =IFERROR(INDEX('Ingredient Database'!$E$5:$E$38,MATCH($A7,'Ingredient Database'!$A$5:$A$38,0))*$C7,"check name") -> 2.5396 | G7: =IFERROR(INDEX('Ingredient Database'!$F$5:$F$38,MATCH($A7,'Ingredient Database'!$A$5:$A$38,0))*$C7,"check name") -> 7.8909 | H7: =IFERROR(INDEX('Ingredient Database'!$G$5:$G$38,MATCH($A7,'Ingredient Database'!$A$5:$A$38,0))*$C7,"check name") -> 0.9977 | I7: =IFERROR(INDEX('Ingredient Database'!$H$5:$H$38,MATCH($A7,'Ingredient Database'!$A$5:$A$38,0))*$C7,"check name") -> 2.4489 | J7: =IFERROR(INDEX('Ingredient Database'!$I$5:$I$38,MATCH($A7,'Ingredient Database'!$A$5:$A$38,0))*$C7,"check name") -> 99.77 | K7: =IFERROR(INDEX('Ingredient Database'!$J$5:$J$38,MATCH($A7,'Ingredient Database'!$A$5:$A$38,0))*$C7,"check name") -> 19.954 | L7: =IFERROR(INDEX('Ingredient Database'!$K$5:$K$38,MATCH($A7,'Ingredient Database'!$A$5:$A$38,0))*$C7,"check name") -> 149.655 | M7: =IFERROR(INDEX('Ingredient Database'!$L$5:$L$38,MATCH($A7,'Ingredient Database'!$A$5:$A$38,0))*$C7,"check name") -> 0.9977 | N7: =IFERROR(INDEX('Ingredient Database'!$M$5:$M$38,MATCH($A7,'Ingredient Database'!$A$5:$A$38,0))*$C7,"check name") -> 0 | O7: =IFERROR(INDEX('Ingredient Database'!$N$5:$N$38,MATCH($A7,'Ingredient Database'!$A$5:$A$38,0))*$C7,"check name") -> 0 | P7: =IFERROR(INDEX('Ingredient Database'!$O$5:$O$38,MATCH($A7,'Ingredient Database'!$A$5:$A$38,0))*$C7,"check name") -> 9.977
A8: Vegetable oil, neutral | B8: 4.5 g (1 tsp) | C8: 0.045 | D8: =IFERROR(INDEX('Ingredient Database'!$C$5:$C$38,MATCH($A8,'Ingredient Database'!$A$5:$A$38,0))*$C8,"check name") -> 39.78 | E8: =IFERROR(INDEX('Ingredient Database'!$D$5:$D$38,MATCH($A8,'Ingredient Database'!$A$5:$A$38,0))*$C8,"check name") -> 0 | F8: =IFERROR(INDEX('Ingredient Database'!$E$5:$E$38,MATCH($A8,'Ingredient Database'!$A$5:$A$38,0))*$C8,"check name") -> 0 | G8: =IFERROR(INDEX('Ingredient Database'!$F$5:$F$38,MATCH($A8,'Ingredient Database'!$A$5:$A$38,0))*$C8,"check name") -> 4.5 | H8: =IFERROR(INDEX('Ingredient Database'!$G$5:$G$38,MATCH($A8,'Ingredient Database'!$A$5:$A$38,0))*$C8,"check name") -> 0 | I8: =IFERROR(INDEX('Ingredient Database'!$H$5:$H$38,MATCH($A8,'Ingredient Database'!$A$5:$A$38,0))*$C8,"check name") -> 0 | J8: =IFERROR(INDEX('Ingredient Database'!$I$5:$I$38,MATCH($A8,'Ingredient Database'!$A$5:$A$38,0))*$C8,"check name") -> 0 | K8: =IFERROR(INDEX('Ingredient Database'!$J$5:$J$38,MATCH($A8,'Ingredient Database'!$A$5:$A$38,0))*$C8,"check name") -> 0 | L8: =IFERROR(INDEX('Ingredient Database'!$K$5:$K$38,MATCH($A8,'Ingredient Database'!$A$5:$A$38,0))*$C8,"check name") -> 0 | M8: =IFERROR(INDEX('Ingredient Database'!$L$5:$L$38,MATCH($A8,'Ingredient Database'!$A$5:$A$38,0))*$C8,"check name") -> 0 | N8: =IFERROR(INDEX('Ingredient Database'!$M$5:$M$38,MATCH($A8,'Ingredient Database'!$A$5:$A$38,0))*$C8,"check name") -> 0 | O8: =IFERROR(INDEX('Ingredient Database'!$N$5:$N$38,MATCH($A8,'Ingredient Database'!$A$5:$A$38,0))*$C8,"check name") -> 0 | P8: =IFERROR(INDEX('Ingredient Database'!$O$5:$O$38,MATCH($A8,'Ingredient Database'!$A$5:$A$38,0))*$C8,"check name") -> 0
A9: Jackfruit, ripe | B9: 50 g | C9: 0.5 | D9: =IFERROR(INDEX('Ingredient Database'!$C$5:$C$38,MATCH($A9,'Ingredient Database'!$A$5:$A$38,0))*$C9,"check name") -> 47.5 | E9: =IFERROR(INDEX('Ingredient Database'!$D$5:$D$38,MATCH($A9,'Ingredient Database'!$A$5:$A$38,0))*$C9,"check name") -> 0.85 | F9: =IFERROR(INDEX('Ingredient Database'!$E$5:$E$38,MATCH($A9,'Ingredient Database'!$A$5:$A$38,0))*$C9,"check name") -> 11.6 | G9: =IFERROR(INDEX('Ingredient Database'!$F$5:$F$38,MATCH($A9,'Ingredient Database'!$A$5:$A$38,0))*$C9,"check name") -> 0.3 | H9: =IFERROR(INDEX('Ingredient Database'!$G$5:$G$38,MATCH($A9,'Ingredient Database'!$A$5:$A$38,0))*$C9,"check name") -> 0.75 | I9: =IFERROR(INDEX('Ingredient Database'!$H$5:$H$38,MATCH($A9,'Ingredient Database'!$A$5:$A$38,0))*$C9,"check name") -> 0.3 | J9: =IFERROR(INDEX('Ingredient Database'!$I$5:$I$38,MATCH($A9,'Ingredient Database'!$A$5:$A$38,0))*$C9,"check name") -> 12 | K9: =IFERROR(INDEX('Ingredient Database'!$J$5:$J$38,MATCH($A9,'Ingredient Database'!$A$5:$A$38,0))*$C9,"check name") -> 14.5 | L9: =IFERROR(INDEX('Ingredient Database'!$K$5:$K$38,MATCH($A9,'Ingredient Database'!$A$5:$A$38,0))*$C9,"check name") -> 224 | M9: =IFERROR(INDEX('Ingredient Database'!$L$5:$L$38,MATCH($A9,'Ingredient Database'!$A$5:$A$38,0))*$C9,"check name") -> 0.2 | N9: =IFERROR(INDEX('Ingredient Database'!$M$5:$M$38,MATCH($A9,'Ingredient Database'!$A$5:$A$38,0))*$C9,"check name") -> 2.5 | O9: =IFERROR(INDEX('Ingredient Database'!$N$5:$N$38,MATCH($A9,'Ingredient Database'!$A$5:$A$38,0))*$C9,"check name") -> 6.85 | P9: =IFERROR(INDEX('Ingredient Database'!$O$5:$O$38,MATCH($A9,'Ingredient Database'!$A$5:$A$38,0))*$C9,"check name") -> 12
A10: Cilantro, chopped | B10: 1 g (1 tsp) | C10: 0.01 | D10: =IFERROR(INDEX('Ingredient Database'!$C$5:$C$38,MATCH($A10,'Ingredient Database'!$A$5:$A$38,0))*$C10,"check name") -> 0.23 | E10: =IFERROR(INDEX('Ingredient Database'!$D$5:$D$38,MATCH($A10,'Ingredient Database'!$A$5:$A$38,0))*$C10,"check name") -> 0.021 | F10: =IFERROR(INDEX('Ingredient Database'!$E$5:$E$38,MATCH($A10,'Ingredient Database'!$A$5:$A$38,0))*$C10,"check name") -> 0.037 | G10: =IFERROR(INDEX('Ingredient Database'!$F$5:$F$38,MATCH($A10,'Ingredient Database'!$A$5:$A$38,0))*$C10,"check name") -> 0.005 | H10: =IFERROR(INDEX('Ingredient Database'!$G$5:$G$38,MATCH($A10,'Ingredient Database'!$A$5:$A$38,0))*$C10,"check name") -> 0.028 | I10: =IFERROR(INDEX('Ingredient Database'!$H$5:$H$38,MATCH($A10,'Ingredient Database'!$A$5:$A$38,0))*$C10,"check name") -> 0.018 | J10: =IFERROR(INDEX('Ingredient Database'!$I$5:$I$38,MATCH($A10,'Ingredient Database'!$A$5:$A$38,0))*$C10,"check name") -> 0.67 | K10: =IFERROR(INDEX('Ingredient Database'!$J$5:$J$38,MATCH($A10,'Ingredient Database'!$A$5:$A$38,0))*$C10,"check name") -> 0.26 | L10: =IFERROR(INDEX('Ingredient Database'!$K$5:$K$38,MATCH($A10,'Ingredient Database'!$A$5:$A$38,0))*$C10,"check name") -> 5.21 | M10: =IFERROR(INDEX('Ingredient Database'!$L$5:$L$38,MATCH($A10,'Ingredient Database'!$A$5:$A$38,0))*$C10,"check name") -> 0.005 | N10: =IFERROR(INDEX('Ingredient Database'!$M$5:$M$38,MATCH($A10,'Ingredient Database'!$A$5:$A$38,0))*$C10,"check name") -> 3.37 | O10: =IFERROR(INDEX('Ingredient Database'!$N$5:$N$38,MATCH($A10,'Ingredient Database'!$A$5:$A$38,0))*$C10,"check name") -> 0.27 | P10: =IFERROR(INDEX('Ingredient Database'!$O$5:$O$38,MATCH($A10,'Ingredient Database'!$A$5:$A$38,0))*$C10,"check name") -> 0.62
A11: Green onion greens, chopped | B11: 1 g (1 tsp) | C11: 0.01 | D11: =IFERROR(INDEX('Ingredient Database'!$C$5:$C$38,MATCH($A11,'Ingredient Database'!$A$5:$A$38,0))*$C11,"check name") -> 0.32 | E11: =IFERROR(INDEX('Ingredient Database'!$D$5:$D$38,MATCH($A11,'Ingredient Database'!$A$5:$A$38,0))*$C11,"check name") -> 0.018 | F11: =IFERROR(INDEX('Ingredient Database'!$E$5:$E$38,MATCH($A11,'Ingredient Database'!$A$5:$A$38,0))*$C11,"check name") -> 0.073 | G11: =IFERROR(INDEX('Ingredient Database'!$F$5:$F$38,MATCH($A11,'Ingredient Database'!$A$5:$A$38,0))*$C11,"check name") -> 0.002 | H11: =IFERROR(INDEX('Ingredient Database'!$G$5:$G$38,MATCH($A11,'Ingredient Database'!$A$5:$A$38,0))*$C11,"check name") -> 0.026 | I11: =IFERROR(INDEX('Ingredient Database'!$H$5:$H$38,MATCH($A11,'Ingredient Database'!$A$5:$A$38,0))*$C11,"check name") -> 0.015 | J11: =IFERROR(INDEX('Ingredient Database'!$I$5:$I$38,MATCH($A11,'Ingredient Database'!$A$5:$A$38,0))*$C11,"check name") -> 0.72 | K11: =IFERROR(INDEX('Ingredient Database'!$J$5:$J$38,MATCH($A11,'Ingredient Database'!$A$5:$A$38,0))*$C11,"check name") -> 0.2 | L11: =IFERROR(INDEX('Ingredient Database'!$K$5:$K$38,MATCH($A11,'Ingredient Database'!$A$5:$A$38,0))*$C11,"check name") -> 2.76 | M11: =IFERROR(INDEX('Ingredient Database'!$L$5:$L$38,MATCH($A11,'Ingredient Database'!$A$5:$A$38,0))*$C11,"check name") -> 0.004 | N11: =IFERROR(INDEX('Ingredient Database'!$M$5:$M$38,MATCH($A11,'Ingredient Database'!$A$5:$A$38,0))*$C11,"check name") -> 0.5 | O11: =IFERROR(INDEX('Ingredient Database'!$N$5:$N$38,MATCH($A11,'Ingredient Database'!$A$5:$A$38,0))*$C11,"check name") -> 0.18 | P11: =IFERROR(INDEX('Ingredient Database'!$O$5:$O$38,MATCH($A11,'Ingredient Database'!$A$5:$A$38,0))*$C11,"check name") -> 0.64
A12: Cabbage & romaine mix | B12: 60 g | C12: 0.6 | D12: =IFERROR(INDEX('Ingredient Database'!$C$5:$C$38,MATCH($A12,'Ingredient Database'!$A$5:$A$38,0))*$C12,"check name") -> 10.8 | E12: =IFERROR(INDEX('Ingredient Database'!$D$5:$D$38,MATCH($A12,'Ingredient Database'!$A$5:$A$38,0))*$C12,"check name") -> 0.84 | F12: =IFERROR(INDEX('Ingredient Database'!$E$5:$E$38,MATCH($A12,'Ingredient Database'!$A$5:$A$38,0))*$C12,"check name") -> 2.1 | G12: =IFERROR(INDEX('Ingredient Database'!$F$5:$F$38,MATCH($A12,'Ingredient Database'!$A$5:$A$38,0))*$C12,"check name") -> 0.12 | H12: =IFERROR(INDEX('Ingredient Database'!$G$5:$G$38,MATCH($A12,'Ingredient Database'!$A$5:$A$38,0))*$C12,"check name") -> 1.08 | I12: =IFERROR(INDEX('Ingredient Database'!$H$5:$H$38,MATCH($A12,'Ingredient Database'!$A$5:$A$38,0))*$C12,"check name") -> 0.3 | J12: =IFERROR(INDEX('Ingredient Database'!$I$5:$I$38,MATCH($A12,'Ingredient Database'!$A$5:$A$38,0))*$C12,"check name") -> 18 | K12: =IFERROR(INDEX('Ingredient Database'!$J$5:$J$38,MATCH($A12,'Ingredient Database'!$A$5:$A$38,0))*$C12,"check name") -> 6 | L12: =IFERROR(INDEX('Ingredient Database'!$K$5:$K$38,MATCH($A12,'Ingredient Database'!$A$5:$A$38,0))*$C12,"check name") -> 120 | M12: =IFERROR(INDEX('Ingredient Database'!$L$5:$L$38,MATCH($A12,'Ingredient Database'!$A$5:$A$38,0))*$C12,"check name") -> 0.12 | N12: =IFERROR(INDEX('Ingredient Database'!$M$5:$M$38,MATCH($A12,'Ingredient Database'!$A$5:$A$38,0))*$C12,"check name") -> 108 | O12: =IFERROR(INDEX('Ingredient Database'!$N$5:$N$38,MATCH($A12,'Ingredient Database'!$A$5:$A$38,0))*$C12,"check name") -> 9 | P12: =IFERROR(INDEX('Ingredient Database'!$O$5:$O$38,MATCH($A12,'Ingredient Database'!$A$5:$A$38,0))*$C12,"check name") -> 30
A13: Carrot & daikon quick pickle | B13: 60 g | C13: 0.6 | D13: =IFERROR(INDEX('Ingredient Database'!$C$5:$C$38,MATCH($A13,'Ingredient Database'!$A$5:$A$38,0))*$C13,"check name") -> 21 | E13: =IFERROR(INDEX('Ingredient Database'!$D$5:$D$38,MATCH($A13,'Ingredient Database'!$A$5:$A$38,0))*$C13,"check name") -> 0.48 | F13: =IFERROR(INDEX('Ingredient Database'!$E$5:$E$38,MATCH($A13,'Ingredient Database'!$A$5:$A$38,0))*$C13,"check name") -> 4.8 | G13: =IFERROR(INDEX('Ingredient Database'!$F$5:$F$38,MATCH($A13,'Ingredient Database'!$A$5:$A$38,0))*$C13,"check name") -> 0.06 | H13: =IFERROR(INDEX('Ingredient Database'!$G$5:$G$38,MATCH($A13,'Ingredient Database'!$A$5:$A$38,0))*$C13,"check name") -> 1.02 | I13: =IFERROR(INDEX('Ingredient Database'!$H$5:$H$38,MATCH($A13,'Ingredient Database'!$A$5:$A$38,0))*$C13,"check name") -> 0.18 | J13: =IFERROR(INDEX('Ingredient Database'!$I$5:$I$38,MATCH($A13,'Ingredient Database'!$A$5:$A$38,0))*$C13,"check name") -> 15 | K13: =IFERROR(INDEX('Ingredient Database'!$J$5:$J$38,MATCH($A13,'Ingredient Database'!$A$5:$A$38,0))*$C13,"check name") -> 6 | L13: =IFERROR(INDEX('Ingredient Database'!$K$5:$K$38,MATCH($A13,'Ingredient Database'!$A$5:$A$38,0))*$C13,"check name") -> 150 | M13: =IFERROR(INDEX('Ingredient Database'!$L$5:$L$38,MATCH($A13,'Ingredient Database'!$A$5:$A$38,0))*$C13,"check name") -> 0.12 | N13: =IFERROR(INDEX('Ingredient Database'!$M$5:$M$38,MATCH($A13,'Ingredient Database'!$A$5:$A$38,0))*$C13,"check name") -> 252 | O13: =IFERROR(INDEX('Ingredient Database'!$N$5:$N$38,MATCH($A13,'Ingredient Database'!$A$5:$A$38,0))*$C13,"check name") -> 7.8 | P13: =IFERROR(INDEX('Ingredient Database'!$O$5:$O$38,MATCH($A13,'Ingredient Database'!$A$5:$A$38,0))*$C13,"check name") -> 9
A14: Chickwheat seitan (Avocados & Ales base recipe) | B14: 50 g | C14: 0.5 | D14: =IFERROR(INDEX('Ingredient Database'!$C$5:$C$38,MATCH($A14,'Ingredient Database'!$A$5:$A$38,0))*$C14,"check name") -> 82.5 | E14: =IFERROR(INDEX('Ingredient Database'!$D$5:$D$38,MATCH($A14,'Ingredient Database'!$A$5:$A$38,0))*$C14,"check name") -> 13 | F14: =IFERROR(INDEX('Ingredient Database'!$E$5:$E$38,MATCH($A14,'Ingredient Database'!$A$5:$A$38,0))*$C14,"check name") -> 2 | G14: =IFERROR(INDEX('Ingredient Database'!$F$5:$F$38,MATCH($A14,'Ingredient Database'!$A$5:$A$38,0))*$C14,"check name") -> 2 | H14: =IFERROR(INDEX('Ingredient Database'!$G$5:$G$38,MATCH($A14,'Ingredient Database'!$A$5:$A$38,0))*$C14,"check name") -> 0.5 | I14: =IFERROR(INDEX('Ingredient Database'!$H$5:$H$38,MATCH($A14,'Ingredient Database'!$A$5:$A$38,0))*$C14,"check name") -> 1.75 | J14: =IFERROR(INDEX('Ingredient Database'!$I$5:$I$38,MATCH($A14,'Ingredient Database'!$A$5:$A$38,0))*$C14,"check name") -> 10 | K14: =IFERROR(INDEX('Ingredient Database'!$J$5:$J$38,MATCH($A14,'Ingredient Database'!$A$5:$A$38,0))*$C14,"check name") -> 12.5 | L14: =IFERROR(INDEX('Ingredient Database'!$K$5:$K$38,MATCH($A14,'Ingredient Database'!$A$5:$A$38,0))*$C14,"check name") -> 45 | M14: =IFERROR(INDEX('Ingredient Database'!$L$5:$L$38,MATCH($A14,'Ingredient Database'!$A$5:$A$38,0))*$C14,"check name") -> 0.6 | N14: =IFERROR(INDEX('Ingredient Database'!$M$5:$M$38,MATCH($A14,'Ingredient Database'!$A$5:$A$38,0))*$C14,"check name") -> 0 | O14: =IFERROR(INDEX('Ingredient Database'!$N$5:$N$38,MATCH($A14,'Ingredient Database'!$A$5:$A$38,0))*$C14,"check name") -> 0 | P14: =IFERROR(INDEX('Ingredient Database'!$O$5:$O$38,MATCH($A14,'Ingredient Database'!$A$5:$A$38,0))*$C14,"check name") -> 2.5
A15: TOTAL | D15: =SUM(D5:D14) -> 595.081 | E15: =SUM(E5:E14) -> 33.0975 | F15: =SUM(F5:F14) -> 58.3196 | G15: =SUM(G5:G14) -> 28.2829 | H15: =SUM(H5:H14) -> 11.1767 | I15: =SUM(I5:I14) -> 6.8219 | J15: =SUM(J5:J14) -> 179.91 | K15: =SUM(K5:K14) -> 98.414 | ... P15: =SUM(P5:P14) -> 96.037

Sheet Recipe - Chana Masala
A1: Chana Masala over Jasmine Rice with Curried Seitan
A2: Per serving — pulls nutrient values live from 'Ingredient Database'
A4: Ingredient (must match database exactly) | B4: Amount (g, or units) | C4: Multiplier (x /100g) | D4: Calories | E4: Protein (g) | F4: Carbs (g) | G4: Fat (g) | H4: Fiber (g) | I4: Iron (mg) | J4: Calcium (mg) | K4: Magnesium (mg) | L4: Potassium (mg) | M4: Zinc (mg) | N4: Vitamin A (mcg) | O4: Vitamin C (mg) | P4: Folate (mcg)
A5: Jasmine rice, cooked | B5: 200 g | C5: 2 | D5: =IFERROR(INDEX('Ingredient Database'!$C$5:$C$38,MATCH($A5,'Ingredient Database'!$A$5:$A$38,0))*$C5,"check name") -> 260 | E5: =IFERROR(INDEX('Ingredient Database'!$D$5:$D$38,MATCH($A5,'Ingredient Database'!$A$5:$A$38,0))*$C5,"check name") -> 5.4 | F5: =IFERROR(INDEX('Ingredient Database'!$E$5:$E$38,MATCH($A5,'Ingredient Database'!$A$5:$A$38,0))*$C5,"check name") -> 56 | G5: =IFERROR(INDEX('Ingredient Database'!$F$5:$F$38,MATCH($A5,'Ingredient Database'!$A$5:$A$38,0))*$C5,"check name") -> 0.6 | H5: =IFERROR(INDEX('Ingredient Database'!$G$5:$G$38,MATCH($A5,'Ingredient Database'!$A$5:$A$38,0))*$C5,"check name") -> 0.8 | I5: =IFERROR(INDEX('Ingredient Database'!$H$5:$H$38,MATCH($A5,'Ingredient Database'!$A$5:$A$38,0))*$C5,"check name") -> 2.4 | J5: =IFERROR(INDEX('Ingredient Database'!$I$5:$I$38,MATCH($A5,'Ingredient Database'!$A$5:$A$38,0))*$C5,"check name") -> 6 | K5: =IFERROR(INDEX('Ingredient Database'!$J$5:$J$38,MATCH($A5,'Ingredient Database'!$A$5:$A$38,0))*$C5,"check name") -> 24 | L5: =IFERROR(INDEX('Ingredient Database'!$K$5:$K$38,MATCH($A5,'Ingredient Database'!$A$5:$A$38,0))*$C5,"check name") -> 70 | M5: =IFERROR(INDEX('Ingredient Database'!$L$5:$L$38,MATCH($A5,'Ingredient Database'!$A$5:$A$38,0))*$C5,"check name") -> 1 | N5: =IFERROR(INDEX('Ingredient Database'!$M$5:$M$38,MATCH($A5,'Ingredient Database'!$A$5:$A$38,0))*$C5,"check name") -> 0 | O5: =IFERROR(INDEX('Ingredient Database'!$N$5:$N$38,MATCH($A5,'Ingredient Database'!$A$5:$A$38,0))*$C5,"check name") -> 0 | P5: =IFERROR(INDEX('Ingredient Database'!$O$5:$O$38,MATCH($A5,'Ingredient Database'!$A$5:$A$38,0))*$C5,"check name") -> 90
A6: Chickpeas, cooked | B6: 75 g | C6: 0.75 | D6: =IFERROR(INDEX('Ingredient Database'!$C$5:$C$38,MATCH($A6,'Ingredient Database'!$A$5:$A$38,0))*$C6,"check name") -> 123 | E6: =IFERROR(INDEX('Ingredient Database'!$D$5:$D$38,MATCH($A6,'Ingredient Database'!$A$5:$A$38,0))*$C6,"check name") -> 6.675 | F6: =IFERROR(INDEX('Ingredient Database'!$E$5:$E$38,MATCH($A6,'Ingredient Database'!$A$5:$A$38,0))*$C6,"check name") -> 20.55 | G6: =IFERROR(INDEX('Ingredient Database'!$F$5:$F$38,MATCH($A6,'Ingredient Database'!$A$5:$A$38,0))*$C6,"check name") -> 1.95 | H6: =IFERROR(INDEX('Ingredient Database'!$G$5:$G$38,MATCH($A6,'Ingredient Database'!$A$5:$A$38,0))*$C6,"check name") -> 5.7 | I6: =IFERROR(INDEX('Ingredient Database'!$H$5:$H$38,MATCH($A6,'Ingredient Database'!$A$5:$A$38,0))*$C6,"check name") -> 2.175 | J6: =IFERROR(INDEX('Ingredient Database'!$I$5:$I$38,MATCH($A6,'Ingredient Database'!$A$5:$A$38,0))*$C6,"check name") -> 36.75 | K6: =IFERROR(INDEX('Ingredient Database'!$J$5:$J$38,MATCH($A6,'Ingredient Database'!$A$5:$A$38,0))*$C6,"check name") -> 36 | L6: =IFERROR(INDEX('Ingredient Database'!$K$5:$K$38,MATCH($A6,'Ingredient Database'!$A$5:$A$38,0))*$C6,"check name") -> 218.25 | M6: =IFERROR(INDEX('Ingredient Database'!$L$5:$L$38,MATCH($A6,'Ingredient Database'!$A$5:$A$38,0))*$C6,"check name") -> 1.125 | N6: =IFERROR(INDEX('Ingredient Database'!$M$5:$M$38,MATCH($A6,'Ingredient Database'!$A$5:$A$38,0))*$C6,"check name") -> 0.75 | O6: =IFERROR(INDEX('Ingredient Database'!$N$5:$N$38,MATCH($A6,'Ingredient Database'!$A$5:$A$38,0))*$C6,"check name") -> 0.975 | P6: =IFERROR(INDEX('Ingredient Database'!$O$5:$O$38,MATCH($A6,'Ingredient Database'!$A$5:$A$38,0))*$C6,"check name") -> 129
A7: Green peas | B7: 20 g | C7: 0.2 | D7: =IFERROR(INDEX('Ingredient Database'!$C$5:$C$38,MATCH($A7,'Ingredient Database'!$A$5:$A$38,0))*$C7,"check name") -> 16.2 | E7: =IFERROR(INDEX('Ingredient Database'!$D$5:$D$38,MATCH($A7,'Ingredient Database'!$A$5:$A$38,0))*$C7,"check name") -> 1.08 | F7: =IFERROR(INDEX('Ingredient Database'!$E$5:$E$38,MATCH($A7,'Ingredient Database'!$A$5:$A$38,0))*$C7,"check name") -> 2.9 | G7: =IFERROR(INDEX('Ingredient Database'!$F$5:$F$38,MATCH($A7,'Ingredient Database'!$A$5:$A$38,0))*$C7,"check name") -> 0.08 | H7: =IFERROR(INDEX('Ingredient Database'!$G$5:$G$38,MATCH($A7,'Ingredient Database'!$A$5:$A$38,0))*$C7,"check name") -> 1.14 | I7: =IFERROR(INDEX('Ingredient Database'!$H$5:$H$38,MATCH($A7,'Ingredient Database'!$A$5:$A$38,0))*$C7,"check name") -> 0.3 | J7: =IFERROR(INDEX('Ingredient Database'!$I$5:$I$38,MATCH($A7,'Ingredient Database'!$A$5:$A$38,0))*$C7,"check name") -> 5 | K7: =IFERROR(INDEX('Ingredient Database'!$J$5:$J$38,MATCH($A7,'Ingredient Database'!$A$5:$A$38,0))*$C7,"check name") -> 6.6 | L7: =IFERROR(INDEX('Ingredient Database'!$K$5:$K$38,MATCH($A7,'Ingredient Database'!$A$5:$A$38,0))*$C7,"check name") -> 48.8 | M7: =IFERROR(INDEX('Ingredient Database'!$L$5:$L$38,MATCH($A7,'Ingredient Database'!$A$5:$A$38,0))*$C7,"check name") -> 0.24 | N7: =IFERROR(INDEX('Ingredient Database'!$M$5:$M$38,MATCH($A7,'Ingredient Database'!$A$5:$A$38,0))*$C7,"check name") -> 7.6 | O7: =IFERROR(INDEX('Ingredient Database'!$N$5:$N$38,MATCH($A7,'Ingredient Database'!$A$5:$A$38,0))*$C7,"check name") -> 8 | P7: =IFERROR(INDEX('Ingredient Database'!$O$5:$O$38,MATCH($A7,'Ingredient Database'!$A$5:$A$38,0))*$C7,"check name") -> 13
A8: Tomato-onion-garlic-ginger-curry leaf base | B8: 55 g | C8: 0.55 | D8: =IFERROR(INDEX('Ingredient Database'!$C$5:$C$38,MATCH($A8,'Ingredient Database'!$A$5:$A$38,0))*$C8,"check name") -> 22 | E8: =IFERROR(INDEX('Ingredient Database'!$D$5:$D$38,MATCH($A8,'Ingredient Database'!$A$5:$A$38,0))*$C8,"check name") -> 0.825 | F8: =IFERROR(INDEX('Ingredient Database'!$E$5:$E$38,MATCH($A8,'Ingredient Database'!$A$5:$A$38,0))*$C8,"check name") -> 4.4 | G8: =IFERROR(INDEX('Ingredient Database'!$F$5:$F$38,MATCH($A8,'Ingredient Database'!$A$5:$A$38,0))*$C8,"check name") -> 0.165 | H8: =IFERROR(INDEX('Ingredient Database'!$G$5:$G$38,MATCH($A8,'Ingredient Database'!$A$5:$A$38,0))*$C8,"check name") -> 0.825 | I8: =IFERROR(INDEX('Ingredient Database'!$H$5:$H$38,MATCH($A8,'Ingredient Database'!$A$5:$A$38,0))*$C8,"check name") -> 0.275 | J8: =IFERROR(INDEX('Ingredient Database'!$I$5:$I$38,MATCH($A8,'Ingredient Database'!$A$5:$A$38,0))*$C8,"check name") -> 8.25 | K8: =IFERROR(INDEX('Ingredient Database'!$J$5:$J$38,MATCH($A8,'Ingredient Database'!$A$5:$A$38,0))*$C8,"check name") -> 5.5 | L8: =IFERROR(INDEX('Ingredient Database'!$K$5:$K$38,MATCH($A8,'Ingredient Database'!$A$5:$A$38,0))*$C8,"check name") -> 121 | M8: =IFERROR(INDEX('Ingredient Database'!$L$5:$L$38,MATCH($A8,'Ingredient Database'!$A$5:$A$38,0))*$C8,"check name") -> 0.11 | N8: =IFERROR(INDEX('Ingredient Database'!$M$5:$M$38,MATCH($A8,'Ingredient Database'!$A$5:$A$38,0))*$C8,"check name") -> 11 | O8: =IFERROR(INDEX('Ingredient Database'!$N$5:$N$38,MATCH($A8,'Ingredient Database'!$A$5:$A$38,0))*$C8,"check name") -> 5.5 | P8: =IFERROR(INDEX('Ingredient Database'!$O$5:$O$38,MATCH($A8,'Ingredient Database'!$A$5:$A$38,0))*$C8,"check name") -> 8.25
A9: Extra virgin olive oil | B9: 2.3 g (1/2 tsp) | C9: 0.023 | D9: =IFERROR(INDEX('Ingredient Database'!$C$5:$C$38,MATCH($A9,'Ingredient Database'!$A$5:$A$38,0))*$C9,"check name") -> 20.332 | E9: =IFERROR(INDEX('Ingredient Database'!$D$5:$D$38,MATCH($A9,'Ingredient Database'!$A$5:$A$38,0))*$C9,"check name") -> 0 | F9: =IFERROR(INDEX('Ingredient Database'!$E$5:$E$38,MATCH($A9,'Ingredient Database'!$A$5:$A$38,0))*$C9,"check name") -> 0 | G9: =IFERROR(INDEX('Ingredient Database'!$F$5:$F$38,MATCH($A9,'Ingredient Database'!$A$5:$A$38,0))*$C9,"check name") -> 2.3 | H9: =IFERROR(INDEX('Ingredient Database'!$G$5:$G$38,MATCH($A9,'Ingredient Database'!$A$5:$A$38,0))*$C9,"check name") -> 0 | I9: =IFERROR(INDEX('Ingredient Database'!$H$5:$H$38,MATCH($A9,'Ingredient Database'!$A$5:$A$38,0))*$C9,"check name") -> 0 | J9: =IFERROR(INDEX('Ingredient Database'!$I$5:$I$38,MATCH($A9,'Ingredient Database'!$A$5:$A$38,0))*$C9,"check name") -> 0 | K9: =IFERROR(INDEX('Ingredient Database'!$J$5:$J$38,MATCH($A9,'Ingredient Database'!$A$5:$A$38,0))*$C9,"check name") -> 0 | L9: =IFERROR(INDEX('Ingredient Database'!$K$5:$K$38,MATCH($A9,'Ingredient Database'!$A$5:$A$38,0))*$C9,"check name") -> 0 | M9: =IFERROR(INDEX('Ingredient Database'!$L$5:$L$38,MATCH($A9,'Ingredient Database'!$A$5:$A$38,0))*$C9,"check name") -> 0 | N9: =IFERROR(INDEX('Ingredient Database'!$M$5:$M$38,MATCH($A9,'Ingredient Database'!$A$5:$A$38,0))*$C9,"check name") -> 0 | O9: =IFERROR(INDEX('Ingredient Database'!$N$5:$N$38,MATCH($A9,'Ingredient Database'!$A$5:$A$38,0))*$C9,"check name") -> 0 | P9: =IFERROR(INDEX('Ingredient Database'!$O$5:$O$38,MATCH($A9,'Ingredient Database'!$A$5:$A$38,0))*$C9,"check name") -> 0
A10: Chickwheat seitan (Avocados & Ales base recipe) | B10: 150 g | C10: 1.5 | D10: =IFERROR(INDEX('Ingredient Database'!$C$5:$C$38,MATCH($A10,'Ingredient Database'!$A$5:$A$38,0))*$C10,"check name") -> 247.5 | E10: =IFERROR(INDEX('Ingredient Database'!$D$5:$D$38,MATCH($A10,'Ingredient Database'!$A$5:$A$38,0))*$C10,"check name") -> 39 | F10: =IFERROR(INDEX('Ingredient Database'!$E$5:$E$38,MATCH($A10,'Ingredient Database'!$A$5:$A$38,0))*$C10,"check name") -> 6 | G10: =IFERROR(INDEX('Ingredient Database'!$F$5:$F$38,MATCH($A10,'Ingredient Database'!$A$5:$A$38,0))*$C10,"check name") -> 6 | H10: =IFERROR(INDEX('Ingredient Database'!$G$5:$G$38,MATCH($A10,'Ingredient Database'!$A$5:$A$38,0))*$C10,"check name") -> 1.5 | I10: =IFERROR(INDEX('Ingredient Database'!$H$5:$H$38,MATCH($A10,'Ingredient Database'!$A$5:$A$38,0))*$C10,"check name") -> 5.25 | J10: =IFERROR(INDEX('Ingredient Database'!$I$5:$I$38,MATCH($A10,'Ingredient Database'!$A$5:$A$38,0))*$C10,"check name") -> 30 | K10: =IFERROR(INDEX('Ingredient Database'!$J$5:$J$38,MATCH($A10,'Ingredient Database'!$A$5:$A$38,0))*$C10,"check name") -> 37.5 | L10: =IFERROR(INDEX('Ingredient Database'!$K$5:$K$38,MATCH($A10,'Ingredient Database'!$A$5:$A$38,0))*$C10,"check name") -> 135 | M10: =IFERROR(INDEX('Ingredient Database'!$L$5:$L$38,MATCH($A10,'Ingredient Database'!$A$5:$A$38,0))*$C10,"check name") -> 1.8 | N10: =IFERROR(INDEX('Ingredient Database'!$M$5:$M$38,MATCH($A10,'Ingredient Database'!$A$5:$A$38,0))*$C10,"check name") -> 0 | O10: =IFERROR(INDEX('Ingredient Database'!$N$5:$N$38,MATCH($A10,'Ingredient Database'!$A$5:$A$38,0))*$C10,"check name") -> 0 | P10: =IFERROR(INDEX('Ingredient Database'!$O$5:$O$38,MATCH($A10,'Ingredient Database'!$A$5:$A$38,0))*$C10,"check name") -> 7.5
A11: Vegetable oil, neutral | B11: 7.5 g (saute) | C11: 0.075 | D11: =IFERROR(INDEX('Ingredient Database'!$C$5:$C$38,MATCH($A11,'Ingredient Database'!$A$5:$A$38,0))*$C11,"check name") -> 66.3 | E11: =IFERROR(INDEX('Ingredient Database'!$D$5:$D$38,MATCH($A11,'Ingredient Database'!$A$5:$A$38,0))*$C11,"check name") -> 0 | F11: =IFERROR(INDEX('Ingredient Database'!$E$5:$E$38,MATCH($A11,'Ingredient Database'!$A$5:$A$38,0))*$C11,"check name") -> 0 | G11: =IFERROR(INDEX('Ingredient Database'!$F$5:$F$38,MATCH($A11,'Ingredient Database'!$A$5:$A$38,0))*$C11,"check name") -> 7.5 | H11: =IFERROR(INDEX('Ingredient Database'!$G$5:$G$38,MATCH($A11,'Ingredient Database'!$A$5:$A$38,0))*$C11,"check name") -> 0 | I11: =IFERROR(INDEX('Ingredient Database'!$H$5:$H$38,MATCH($A11,'Ingredient Database'!$A$5:$A$38,0))*$C11,"check name") -> 0 | J11: =IFERROR(INDEX('Ingredient Database'!$I$5:$I$38,MATCH($A11,'Ingredient Database'!$A$5:$A$38,0))*$C11,"check name") -> 0 | K11: =IFERROR(INDEX('Ingredient Database'!$J$5:$J$38,MATCH($A11,'Ingredient Database'!$A$5:$A$38,0))*$C11,"check name") -> 0 | L11: =IFERROR(INDEX('Ingredient Database'!$K$5:$K$38,MATCH($A11,'Ingredient Database'!$A$5:$A$38,0))*$C11,"check name") -> 0 | M11: =IFERROR(INDEX('Ingredient Database'!$L$5:$L$38,MATCH($A11,'Ingredient Database'!$A$5:$A$38,0))*$C11,"check name") -> 0 | N11: =IFERROR(INDEX('Ingredient Database'!$M$5:$M$38,MATCH($A11,'Ingredient Database'!$A$5:$A$38,0))*$C11,"check name") -> 0 | O11: =IFERROR(INDEX('Ingredient Database'!$N$5:$N$38,MATCH($A11,'Ingredient Database'!$A$5:$A$38,0))*$C11,"check name") -> 0 | P11: =IFERROR(INDEX('Ingredient Database'!$O$5:$O$38,MATCH($A11,'Ingredient Database'!$A$5:$A$38,0))*$C11,"check name") -> 0
A12: Garlic clove | B12: 1 clove | C12: 1 | D12: =IFERROR(INDEX('Ingredient Database'!$C$5:$C$38,MATCH($A12,'Ingredient Database'!$A$5:$A$38,0))*$C12,"check name") -> 4.5 | E12: =IFERROR(INDEX('Ingredient Database'!$D$5:$D$38,MATCH($A12,'Ingredient Database'!$A$5:$A$38,0))*$C12,"check name") -> 0.19 | F12: =IFERROR(INDEX('Ingredient Database'!$E$5:$E$38,MATCH($A12,'Ingredient Database'!$A$5:$A$38,0))*$C12,"check name") -> 1 | G12: =IFERROR(INDEX('Ingredient Database'!$F$5:$F$38,MATCH($A12,'Ingredient Database'!$A$5:$A$38,0))*$C12,"check name") -> 0.02 | H12: =IFERROR(INDEX('Ingredient Database'!$G$5:$G$38,MATCH($A12,'Ingredient Database'!$A$5:$A$38,0))*$C12,"check name") -> 0 | I12: =IFERROR(INDEX('Ingredient Database'!$H$5:$H$38,MATCH($A12,'Ingredient Database'!$A$5:$A$38,0))*$C12,"check name") -> 0.05 | J12: =IFERROR(INDEX('Ingredient Database'!$I$5:$I$38,MATCH($A12,'Ingredient Database'!$A$5:$A$38,0))*$C12,"check name") -> 5 | K12: =IFERROR(INDEX('Ingredient Database'!$J$5:$J$38,MATCH($A12,'Ingredient Database'!$A$5:$A$38,0))*$C12,"check name") -> 0 | L12: =IFERROR(INDEX('Ingredient Database'!$K$5:$K$38,MATCH($A12,'Ingredient Database'!$A$5:$A$38,0))*$C12,"check name") -> 12 | M12: =IFERROR(INDEX('Ingredient Database'!$L$5:$L$38,MATCH($A12,'Ingredient Database'!$A$5:$A$38,0))*$C12,"check name") -> 0 | N12: =IFERROR(INDEX('Ingredient Database'!$M$5:$M$38,MATCH($A12,'Ingredient Database'!$A$5:$A$38,0))*$C12,"check name") -> 0 | O12: =IFERROR(INDEX('Ingredient Database'!$N$5:$N$38,MATCH($A12,'Ingredient Database'!$A$5:$A$38,0))*$C12,"check name") -> 0 | P12: =IFERROR(INDEX('Ingredient Database'!$O$5:$O$38,MATCH($A12,'Ingredient Database'!$A$5:$A$38,0))*$C12,"check name") -> 0
A13: Cilantro, chopped | B13: 1 g (1 tsp, garnish) | C13: 0.01 | D13: =IFERROR(INDEX('Ingredient Database'!$C$5:$C$38,MATCH($A13,'Ingredient Database'!$A$5:$A$38,0))*$C13,"check name") -> 0.23 | E13: =IFERROR(INDEX('Ingredient Database'!$D$5:$D$38,MATCH($A13,'Ingredient Database'!$A$5:$A$38,0))*$C13,"check name") -> 0.021 | F13: =IFERROR(INDEX('Ingredient Database'!$E$5:$E$38,MATCH($A13,'Ingredient Database'!$A$5:$A$38,0))*$C13,"check name") -> 0.037 | G13: =IFERROR(INDEX('Ingredient Database'!$F$5:$F$38,MATCH($A13,'Ingredient Database'!$A$5:$A$38,0))*$C13,"check name") -> 0.005 | H13: =IFERROR(INDEX('Ingredient Database'!$G$5:$G$38,MATCH($A13,'Ingredient Database'!$A$5:$A$38,0))*$C13,"check name") -> 0.028 | I13: =IFERROR(INDEX('Ingredient Database'!$H$5:$H$38,MATCH($A13,'Ingredient Database'!$A$5:$A$38,0))*$C13,"check name") -> 0.018 | J13: =IFERROR(INDEX('Ingredient Database'!$I$5:$I$38,MATCH($A13,'Ingredient Database'!$A$5:$A$38,0))*$C13,"check name") -> 0.67 | K13: =IFERROR(INDEX('Ingredient Database'!$J$5:$J$38,MATCH($A13,'Ingredient Database'!$A$5:$A$38,0))*$C13,"check name") -> 0.26 | L13: =IFERROR(INDEX('Ingredient Database'!$K$5:$K$38,MATCH($A13,'Ingredient Database'!$A$5:$A$38,0))*$C13,"check name") -> 5.21 | M13: =IFERROR(INDEX('Ingredient Database'!$L$5:$L$38,MATCH($A13,'Ingredient Database'!$A$5:$A$38,0))*$C13,"check name") -> 0.005 | N13: =IFERROR(INDEX('Ingredient Database'!$M$5:$M$38,MATCH($A13,'Ingredient Database'!$A$5:$A$38,0))*$C13,"check name") -> 3.37 | O13: =IFERROR(INDEX('Ingredient Database'!$N$5:$N$38,MATCH($A13,'Ingredient Database'!$A$5:$A$38,0))*$C13,"check name") -> 0.27 | P13: =IFERROR(INDEX('Ingredient Database'!$O$5:$O$38,MATCH($A13,'Ingredient Database'!$A$5:$A$38,0))*$C13,"check name") -> 0.62
A14: TOTAL | D14: =SUM(D5:D13) -> 760.062 | E14: =SUM(E5:E13) -> 53.191 | F14: =SUM(F5:F13) -> 90.887 | G14: =SUM(G5:G13) -> 18.62 | H14: =SUM(H5:H13) -> 9.993 | I14: =SUM(I5:I13) -> 10.468 | J14: =SUM(J5:J13) -> 91.67 | K14: =SUM(K5:K13) -> 109.86 | ... P14: =SUM(P5:P13) -> 248.37

Sheet Recipe - Burrito
A1: Parboiled Rice, Black Lentil & Seitan Burrito
A2: Per burrito — pulls nutrient values live from 'Ingredient Database'
A4: Ingredient (must match database exactly) | B4: Amount (g, or units) | C4: Multiplier (x /100g) | D4: Calories | E4: Protein (g) | F4: Carbs (g) | G4: Fat (g) | H4: Fiber (g) | I4: Iron (mg) | J4: Calcium (mg) | K4: Magnesium (mg) | L4: Potassium (mg) | M4: Zinc (mg) | N4: Vitamin A (mcg) | O4: Vitamin C (mg) | P4: Folate (mcg)
A5: La Banderita super burrito flour tortilla | B5: 90 g | C5: 0.9 | D5: =IFERROR(INDEX('Ingredient Database'!$C$5:$C$38,MATCH($A5,'Ingredient Database'!$A$5:$A$38,0))*$C5,"check name") -> 299.7 | E5: =IFERROR(INDEX('Ingredient Database'!$D$5:$D$38,MATCH($A5,'Ingredient Database'!$A$5:$A$38,0))*$C5,"check name") -> 8.01 | F5: =IFERROR(INDEX('Ingredient Database'!$E$5:$E$38,MATCH($A5,'Ingredient Database'!$A$5:$A$38,0))*$C5,"check name") -> 50.4 | G5: =IFERROR(INDEX('Ingredient Database'!$F$5:$F$38,MATCH($A5,'Ingredient Database'!$A$5:$A$38,0))*$C5,"check name") -> 7.02 | H5: =IFERROR(INDEX('Ingredient Database'!$G$5:$G$38,MATCH($A5,'Ingredient Database'!$A$5:$A$38,0))*$C5,"check name") -> 2.25 | I5: =IFERROR(INDEX('Ingredient Database'!$H$5:$H$38,MATCH($A5,'Ingredient Database'!$A$5:$A$38,0))*$C5,"check name") -> 2.34 | J5: =IFERROR(INDEX('Ingredient Database'!$I$5:$I$38,MATCH($A5,'Ingredient Database'!$A$5:$A$38,0))*$C5,"check name") -> 72 | K5: =IFERROR(INDEX('Ingredient Database'!$J$5:$J$38,MATCH($A5,'Ingredient Database'!$A$5:$A$38,0))*$C5,"check name") -> 18 | L5: =IFERROR(INDEX('Ingredient Database'!$K$5:$K$38,MATCH($A5,'Ingredient Database'!$A$5:$A$38,0))*$C5,"check name") -> 90 | M5: =IFERROR(INDEX('Ingredient Database'!$L$5:$L$38,MATCH($A5,'Ingredient Database'!$A$5:$A$38,0))*$C5,"check name") -> 0.54 | N5: =IFERROR(INDEX('Ingredient Database'!$M$5:$M$38,MATCH($A5,'Ingredient Database'!$A$5:$A$38,0))*$C5,"check name") -> 0 | O5: =IFERROR(INDEX('Ingredient Database'!$N$5:$N$38,MATCH($A5,'Ingredient Database'!$A$5:$A$38,0))*$C5,"check name") -> 0 | P5: =IFERROR(INDEX('Ingredient Database'!$O$5:$O$38,MATCH($A5,'Ingredient Database'!$A$5:$A$38,0))*$C5,"check name") -> 90
A6: Chickwheat seitan (Avocados & Ales base recipe) | B6: 50 g | C6: 0.5 | D6: =IFERROR(INDEX('Ingredient Database'!$C$5:$C$38,MATCH($A6,'Ingredient Database'!$A$5:$A$38,0))*$C6,"check name") -> 82.5 | E6: =IFERROR(INDEX('Ingredient Database'!$D$5:$D$38,MATCH($A6,'Ingredient Database'!$A$5:$A$38,0))*$C6,"check name") -> 13 | F6: =IFERROR(INDEX('Ingredient Database'!$E$5:$E$38,MATCH($A6,'Ingredient Database'!$A$5:$A$38,0))*$C6,"check name") -> 2 | G6: =IFERROR(INDEX('Ingredient Database'!$F$5:$F$38,MATCH($A6,'Ingredient Database'!$A$5:$A$38,0))*$C6,"check name") -> 2 | H6: =IFERROR(INDEX('Ingredient Database'!$G$5:$G$38,MATCH($A6,'Ingredient Database'!$A$5:$A$38,0))*$C6,"check name") -> 0.5 | I6: =IFERROR(INDEX('Ingredient Database'!$H$5:$H$38,MATCH($A6,'Ingredient Database'!$A$5:$A$38,0))*$C6,"check name") -> 1.75 | J6: =IFERROR(INDEX('Ingredient Database'!$I$5:$I$38,MATCH($A6,'Ingredient Database'!$A$5:$A$38,0))*$C6,"check name") -> 10 | K6: =IFERROR(INDEX('Ingredient Database'!$J$5:$J$38,MATCH($A6,'Ingredient Database'!$A$5:$A$38,0))*$C6,"check name") -> 12.5 | L6: =IFERROR(INDEX('Ingredient Database'!$K$5:$K$38,MATCH($A6,'Ingredient Database'!$A$5:$A$38,0))*$C6,"check name") -> 45 | M6: =IFERROR(INDEX('Ingredient Database'!$L$5:$L$38,MATCH($A6,'Ingredient Database'!$A$5:$A$38,0))*$C6,"check name") -> 0.6 | N6: =IFERROR(INDEX('Ingredient Database'!$M$5:$M$38,MATCH($A6,'Ingredient Database'!$A$5:$A$38,0))*$C6,"check name") -> 0 | O6: =IFERROR(INDEX('Ingredient Database'!$N$5:$N$38,MATCH($A6,'Ingredient Database'!$A$5:$A$38,0))*$C6,"check name") -> 0 | P6: =IFERROR(INDEX('Ingredient Database'!$O$5:$O$38,MATCH($A6,'Ingredient Database'!$A$5:$A$38,0))*$C6,"check name") -> 2.5
A7: Black lentils, dry curry style (garlic, onion, turmeric, cumin, chile) | B7: 125 g | C7: 1.25 | D7: =IFERROR(INDEX('Ingredient Database'!$C$5:$C$38,MATCH($A7,'Ingredient Database'!$A$5:$A$38,0))*$C7,"check name") -> 208.75 | E7: =IFERROR(INDEX('Ingredient Database'!$D$5:$D$38,MATCH($A7,'Ingredient Database'!$A$5:$A$38,0))*$C7,"check name") -> 16.25 | F7: =IFERROR(INDEX('Ingredient Database'!$E$5:$E$38,MATCH($A7,'Ingredient Database'!$A$5:$A$38,0))*$C7,"check name") -> 31.25 | G7: =IFERROR(INDEX('Ingredient Database'!$F$5:$F$38,MATCH($A7,'Ingredient Database'!$A$5:$A$38,0))*$C7,"check name") -> 1.875 | H7: =IFERROR(INDEX('Ingredient Database'!$G$5:$G$38,MATCH($A7,'Ingredient Database'!$A$5:$A$38,0))*$C7,"check name") -> 10 | I7: =IFERROR(INDEX('Ingredient Database'!$H$5:$H$38,MATCH($A7,'Ingredient Database'!$A$5:$A$38,0))*$C7,"check name") -> 5.9 | J7: =IFERROR(INDEX('Ingredient Database'!$I$5:$I$38,MATCH($A7,'Ingredient Database'!$A$5:$A$38,0))*$C7,"check name") -> 31.25 | K7: =IFERROR(INDEX('Ingredient Database'!$J$5:$J$38,MATCH($A7,'Ingredient Database'!$A$5:$A$38,0))*$C7,"check name") -> 56.25 | L7: =IFERROR(INDEX('Ingredient Database'!$K$5:$K$38,MATCH($A7,'Ingredient Database'!$A$5:$A$38,0))*$C7,"check name") -> 462.5 | M7: =IFERROR(INDEX('Ingredient Database'!$L$5:$L$38,MATCH($A7,'Ingredient Database'!$A$5:$A$38,0))*$C7,"check name") -> 2.5 | N7: =IFERROR(INDEX('Ingredient Database'!$M$5:$M$38,MATCH($A7,'Ingredient Database'!$A$5:$A$38,0))*$C7,"check name") -> 0 | O7: =IFERROR(INDEX('Ingredient Database'!$N$5:$N$38,MATCH($A7,'Ingredient Database'!$A$5:$A$38,0))*$C7,"check name") -> 2.5 | P7: =IFERROR(INDEX('Ingredient Database'!$O$5:$O$38,MATCH($A7,'Ingredient Database'!$A$5:$A$38,0))*$C7,"check name") -> 225
A8: Parboiled rice, cooked | B8: 50 g | C8: 0.5 | D8: =IFERROR(INDEX('Ingredient Database'!$C$5:$C$38,MATCH($A8,'Ingredient Database'!$A$5:$A$38,0))*$C8,"check name") -> 61.5 | E8: =IFERROR(INDEX('Ingredient Database'!$D$5:$D$38,MATCH($A8,'Ingredient Database'!$A$5:$A$38,0))*$C8,"check name") -> 1.3 | F8: =IFERROR(INDEX('Ingredient Database'!$E$5:$E$38,MATCH($A8,'Ingredient Database'!$A$5:$A$38,0))*$C8,"check name") -> 13 | G8: =IFERROR(INDEX('Ingredient Database'!$F$5:$F$38,MATCH($A8,'Ingredient Database'!$A$5:$A$38,0))*$C8,"check name") -> 0.1 | H8: =IFERROR(INDEX('Ingredient Database'!$G$5:$G$38,MATCH($A8,'Ingredient Database'!$A$5:$A$38,0))*$C8,"check name") -> 0.2 | I8: =IFERROR(INDEX('Ingredient Database'!$H$5:$H$38,MATCH($A8,'Ingredient Database'!$A$5:$A$38,0))*$C8,"check name") -> 0.25 | J8: =IFERROR(INDEX('Ingredient Database'!$I$5:$I$38,MATCH($A8,'Ingredient Database'!$A$5:$A$38,0))*$C8,"check name") -> 1.5 | K8: =IFERROR(INDEX('Ingredient Database'!$J$5:$J$38,MATCH($A8,'Ingredient Database'!$A$5:$A$38,0))*$C8,"check name") -> 7.5 | L8: =IFERROR(INDEX('Ingredient Database'!$K$5:$K$38,MATCH($A8,'Ingredient Database'!$A$5:$A$38,0))*$C8,"check name") -> 22.5 | M8: =IFERROR(INDEX('Ingredient Database'!$L$5:$L$38,MATCH($A8,'Ingredient Database'!$A$5:$A$38,0))*$C8,"check name") -> 0.25 | N8: =IFERROR(INDEX('Ingredient Database'!$M$5:$M$38,MATCH($A8,'Ingredient Database'!$A$5:$A$38,0))*$C8,"check name") -> 0 | O8: =IFERROR(INDEX('Ingredient Database'!$N$5:$N$38,MATCH($A8,'Ingredient Database'!$A$5:$A$38,0))*$C8,"check name") -> 0 | P8: =IFERROR(INDEX('Ingredient Database'!$O$5:$O$38,MATCH($A8,'Ingredient Database'!$A$5:$A$38,0))*$C8,"check name") -> 10
A9: Napa cabbage, carrot & daikon slaw (vinegar) | B9: 40 g | C9: 0.4 | D9: =IFERROR(INDEX('Ingredient Database'!$C$5:$C$38,MATCH($A9,'Ingredient Database'!$A$5:$A$38,0))*$C9,"check name") -> 10 | E9: =IFERROR(INDEX('Ingredient Database'!$D$5:$D$38,MATCH($A9,'Ingredient Database'!$A$5:$A$38,0))*$C9,"check name") -> 0.4 | F9: =IFERROR(INDEX('Ingredient Database'!$E$5:$E$38,MATCH($A9,'Ingredient Database'!$A$5:$A$38,0))*$C9,"check name") -> 2.3 | G9: =IFERROR(INDEX('Ingredient Database'!$F$5:$F$38,MATCH($A9,'Ingredient Database'!$A$5:$A$38,0))*$C9,"check name") -> 0 | H9: =IFERROR(INDEX('Ingredient Database'!$G$5:$G$38,MATCH($A9,'Ingredient Database'!$A$5:$A$38,0))*$C9,"check name") -> 0.6 | I9: =IFERROR(INDEX('Ingredient Database'!$H$5:$H$38,MATCH($A9,'Ingredient Database'!$A$5:$A$38,0))*$C9,"check name") -> 0.16 | J9: =IFERROR(INDEX('Ingredient Database'!$I$5:$I$38,MATCH($A9,'Ingredient Database'!$A$5:$A$38,0))*$C9,"check name") -> 12 | K9: =IFERROR(INDEX('Ingredient Database'!$J$5:$J$38,MATCH($A9,'Ingredient Database'!$A$5:$A$38,0))*$C9,"check name") -> 4 | L9: =IFERROR(INDEX('Ingredient Database'!$K$5:$K$38,MATCH($A9,'Ingredient Database'!$A$5:$A$38,0))*$C9,"check name") -> 72 | M9: =IFERROR(INDEX('Ingredient Database'!$L$5:$L$38,MATCH($A9,'Ingredient Database'!$A$5:$A$38,0))*$C9,"check name") -> 0.08 | N9: =IFERROR(INDEX('Ingredient Database'!$M$5:$M$38,MATCH($A9,'Ingredient Database'!$A$5:$A$38,0))*$C9,"check name") -> 32 | O9: =IFERROR(INDEX('Ingredient Database'!$N$5:$N$38,MATCH($A9,'Ingredient Database'!$A$5:$A$38,0))*$C9,"check name") -> 10 | P9: =IFERROR(INDEX('Ingredient Database'!$O$5:$O$38,MATCH($A9,'Ingredient Database'!$A$5:$A$38,0))*$C9,"check name") -> 8
A10: TOTAL | D10: =SUM(D5:D9) -> 662.45 | E10: =SUM(E5:E9) -> 38.96 | F10: =SUM(F5:F9) -> 98.95 | G10: =SUM(G5:G9) -> 10.995 | H10: =SUM(H5:H9) -> 13.55 | I10: =SUM(I5:I9) -> 10.4 | J10: =SUM(J5:J9) -> 126.75 | K10: =SUM(K5:K9) -> 98.25 | ... P10: =SUM(P5:P9) -> 335.5

Sheet Recipe - Muffins
A1: Seedy Oatmeal Muffins (batch of 9)
A2: Batch total — pulls nutrient values live from 'Ingredient Database'
A4: Ingredient (must match database exactly) | B4: Amount (g, or units) | C4: Multiplier (x /100g) | D4: Calories | E4: Protein (g) | F4: Carbs (g) | G4: Fat (g) | H4: Fiber (g) | I4: Iron (mg) | J4: Calcium (mg) | K4: Magnesium (mg) | L4: Potassium (mg) | M4: Zinc (mg) | N4: Vitamin A (mcg) | O4: Vitamin C (mg) | P4: Folate (mcg)
A5: Rolled oats, dry | B5: 180 g | C5: 1.8 | D5: =IFERROR(INDEX('Ingredient Database'!$C$5:$C$38,MATCH($A5,'Ingredient Database'!$A$5:$A$38,0))*$C5,"check name") -> 700.2 | E5: =IFERROR(INDEX('Ingredient Database'!$D$5:$D$38,MATCH($A5,'Ingredient Database'!$A$5:$A$38,0))*$C5,"check name") -> 30.42 | F5: =IFERROR(INDEX('Ingredient Database'!$E$5:$E$38,MATCH($A5,'Ingredient Database'!$A$5:$A$38,0))*$C5,"check name") -> 119.34 | G5: =IFERROR(INDEX('Ingredient Database'!$F$5:$F$38,MATCH($A5,'Ingredient Database'!$A$5:$A$38,0))*$C5,"check name") -> 12.42 | H5: =IFERROR(INDEX('Ingredient Database'!$G$5:$G$38,MATCH($A5,'Ingredient Database'!$A$5:$A$38,0))*$C5,"check name") -> 19.08 | I5: =IFERROR(INDEX('Ingredient Database'!$H$5:$H$38,MATCH($A5,'Ingredient Database'!$A$5:$A$38,0))*$C5,"check name") -> 8.46 | J5: =IFERROR(INDEX('Ingredient Database'!$I$5:$I$38,MATCH($A5,'Ingredient Database'!$A$5:$A$38,0))*$C5,"check name") -> 97.2 | K5: =IFERROR(INDEX('Ingredient Database'!$J$5:$J$38,MATCH($A5,'Ingredient Database'!$A$5:$A$38,0))*$C5,"check name") -> 248.4 | L5: =IFERROR(INDEX('Ingredient Database'!$K$5:$K$38,MATCH($A5,'Ingredient Database'!$A$5:$A$38,0))*$C5,"check name") -> 772.2 | M5: =IFERROR(INDEX('Ingredient Database'!$L$5:$L$38,MATCH($A5,'Ingredient Database'!$A$5:$A$38,0))*$C5,"check name") -> 7.146 | N5: =IFERROR(INDEX('Ingredient Database'!$M$5:$M$38,MATCH($A5,'Ingredient Database'!$A$5:$A$38,0))*$C5,"check name") -> 0 | O5: =IFERROR(INDEX('Ingredient Database'!$N$5:$N$38,MATCH($A5,'Ingredient Database'!$A$5:$A$38,0))*$C5,"check name") -> 0 | P5: =IFERROR(INDEX('Ingredient Database'!$O$5:$O$38,MATCH($A5,'Ingredient Database'!$A$5:$A$38,0))*$C5,"check name") -> 100.8
A6: All-purpose flour, enriched | B6: 140 g | C6: 1.4 | D6: =IFERROR(INDEX('Ingredient Database'!$C$5:$C$38,MATCH($A6,'Ingredient Database'!$A$5:$A$38,0))*$C6,"check name") -> 509.6 | E6: =IFERROR(INDEX('Ingredient Database'!$D$5:$D$38,MATCH($A6,'Ingredient Database'!$A$5:$A$38,0))*$C6,"check name") -> 14.42 | F6: =IFERROR(INDEX('Ingredient Database'!$E$5:$E$38,MATCH($A6,'Ingredient Database'!$A$5:$A$38,0))*$C6,"check name") -> 106.82 | G6: =IFERROR(INDEX('Ingredient Database'!$F$5:$F$38,MATCH($A6,'Ingredient Database'!$A$5:$A$38,0))*$C6,"check name") -> 1.4 | H6: =IFERROR(INDEX('Ingredient Database'!$G$5:$G$38,MATCH($A6,'Ingredient Database'!$A$5:$A$38,0))*$C6,"check name") -> 3.78 | I6: =IFERROR(INDEX('Ingredient Database'!$H$5:$H$38,MATCH($A6,'Ingredient Database'!$A$5:$A$38,0))*$C6,"check name") -> 6.44 | J6: =IFERROR(INDEX('Ingredient Database'!$I$5:$I$38,MATCH($A6,'Ingredient Database'!$A$5:$A$38,0))*$C6,"check name") -> 21 | K6: =IFERROR(INDEX('Ingredient Database'!$J$5:$J$38,MATCH($A6,'Ingredient Database'!$A$5:$A$38,0))*$C6,"check name") -> 30.8 | L6: =IFERROR(INDEX('Ingredient Database'!$K$5:$K$38,MATCH($A6,'Ingredient Database'!$A$5:$A$38,0))*$C6,"check name") -> 149.8 | M6: =IFERROR(INDEX('Ingredient Database'!$L$5:$L$38,MATCH($A6,'Ingredient Database'!$A$5:$A$38,0))*$C6,"check name") -> 0.98 | N6: =IFERROR(INDEX('Ingredient Database'!$M$5:$M$38,MATCH($A6,'Ingredient Database'!$A$5:$A$38,0))*$C6,"check name") -> 0 | O6: =IFERROR(INDEX('Ingredient Database'!$N$5:$N$38,MATCH($A6,'Ingredient Database'!$A$5:$A$38,0))*$C6,"check name") -> 0 | P6: =IFERROR(INDEX('Ingredient Database'!$O$5:$O$38,MATCH($A6,'Ingredient Database'!$A$5:$A$38,0))*$C6,"check name") -> 256.2
A7: Chia seeds | B7: 36 g (3 tbsp) | C7: 0.36 | D7: =IFERROR(INDEX('Ingredient Database'!$C$5:$C$38,MATCH($A7,'Ingredient Database'!$A$5:$A$38,0))*$C7,"check name") -> 174.96 | E7: =IFERROR(INDEX('Ingredient Database'!$D$5:$D$38,MATCH($A7,'Ingredient Database'!$A$5:$A$38,0))*$C7,"check name") -> 5.94 | F7: =IFERROR(INDEX('Ingredient Database'!$E$5:$E$38,MATCH($A7,'Ingredient Database'!$A$5:$A$38,0))*$C7,"check name") -> 15.156 | G7: =IFERROR(INDEX('Ingredient Database'!$F$5:$F$38,MATCH($A7,'Ingredient Database'!$A$5:$A$38,0))*$C7,"check name") -> 11.052 | H7: =IFERROR(INDEX('Ingredient Database'!$G$5:$G$38,MATCH($A7,'Ingredient Database'!$A$5:$A$38,0))*$C7,"check name") -> 12.384 | I7: =IFERROR(INDEX('Ingredient Database'!$H$5:$H$38,MATCH($A7,'Ingredient Database'!$A$5:$A$38,0))*$C7,"check name") -> 2.772 | J7: =IFERROR(INDEX('Ingredient Database'!$I$5:$I$38,MATCH($A7,'Ingredient Database'!$A$5:$A$38,0))*$C7,"check name") -> 227.16 | K7: =IFERROR(INDEX('Ingredient Database'!$J$5:$J$38,MATCH($A7,'Ingredient Database'!$A$5:$A$38,0))*$C7,"check name") -> 120.6 | L7: =IFERROR(INDEX('Ingredient Database'!$K$5:$K$38,MATCH($A7,'Ingredient Database'!$A$5:$A$38,0))*$C7,"check name") -> 146.52 | M7: =IFERROR(INDEX('Ingredient Database'!$L$5:$L$38,MATCH($A7,'Ingredient Database'!$A$5:$A$38,0))*$C7,"check name") -> 1.656 | N7: =IFERROR(INDEX('Ingredient Database'!$M$5:$M$38,MATCH($A7,'Ingredient Database'!$A$5:$A$38,0))*$C7,"check name") -> 0 | O7: =IFERROR(INDEX('Ingredient Database'!$N$5:$N$38,MATCH($A7,'Ingredient Database'!$A$5:$A$38,0))*$C7,"check name") -> 0 | P7: =IFERROR(INDEX('Ingredient Database'!$O$5:$O$38,MATCH($A7,'Ingredient Database'!$A$5:$A$38,0))*$C7,"check name") -> 17.64
A8: Cinnamon, ground | B8: 2.3 g (1 tsp) | C8: 0.023 | D8: =IFERROR(INDEX('Ingredient Database'!$C$5:$C$38,MATCH($A8,'Ingredient Database'!$A$5:$A$38,0))*$C8,"check name") -> 5.681 | E8: =IFERROR(INDEX('Ingredient Database'!$D$5:$D$38,MATCH($A8,'Ingredient Database'!$A$5:$A$38,0))*$C8,"check name") -> 0.092 | F8: =IFERROR(INDEX('Ingredient Database'!$E$5:$E$38,MATCH($A8,'Ingredient Database'!$A$5:$A$38,0))*$C8,"check name") -> 1.863 | G8: =IFERROR(INDEX('Ingredient Database'!$F$5:$F$38,MATCH($A8,'Ingredient Database'!$A$5:$A$38,0))*$C8,"check name") -> 0.0276 | H8: =IFERROR(INDEX('Ingredient Database'!$G$5:$G$38,MATCH($A8,'Ingredient Database'!$A$5:$A$38,0))*$C8,"check name") -> 1.219 | I8: =IFERROR(INDEX('Ingredient Database'!$H$5:$H$38,MATCH($A8,'Ingredient Database'!$A$5:$A$38,0))*$C8,"check name") -> 0.1909 | J8: =IFERROR(INDEX('Ingredient Database'!$I$5:$I$38,MATCH($A8,'Ingredient Database'!$A$5:$A$38,0))*$C8,"check name") -> 23.046 | K8: =IFERROR(INDEX('Ingredient Database'!$J$5:$J$38,MATCH($A8,'Ingredient Database'!$A$5:$A$38,0))*$C8,"check name") -> 1.38 | L8: =IFERROR(INDEX('Ingredient Database'!$K$5:$K$38,MATCH($A8,'Ingredient Database'!$A$5:$A$38,0))*$C8,"check name") -> 9.913 | M8: =IFERROR(INDEX('Ingredient Database'!$L$5:$L$38,MATCH($A8,'Ingredient Database'!$A$5:$A$38,0))*$C8,"check name") -> 0.0414 | N8: =IFERROR(INDEX('Ingredient Database'!$M$5:$M$38,MATCH($A8,'Ingredient Database'!$A$5:$A$38,0))*$C8,"check name") -> 0.023 | O8: =IFERROR(INDEX('Ingredient Database'!$N$5:$N$38,MATCH($A8,'Ingredient Database'!$A$5:$A$38,0))*$C8,"check name") -> 0.092 | P8: =IFERROR(INDEX('Ingredient Database'!$O$5:$O$38,MATCH($A8,'Ingredient Database'!$A$5:$A$38,0))*$C8,"check name") -> 0.138
A9: Cloves, ground | B9: 2.3 g (1 tsp) | C9: 0.023 | D9: =IFERROR(INDEX('Ingredient Database'!$C$5:$C$38,MATCH($A9,'Ingredient Database'!$A$5:$A$38,0))*$C9,"check name") -> 6.302 | E9: =IFERROR(INDEX('Ingredient Database'!$D$5:$D$38,MATCH($A9,'Ingredient Database'!$A$5:$A$38,0))*$C9,"check name") -> 0.138 | F9: =IFERROR(INDEX('Ingredient Database'!$E$5:$E$38,MATCH($A9,'Ingredient Database'!$A$5:$A$38,0))*$C9,"check name") -> 1.5065 | G9: =IFERROR(INDEX('Ingredient Database'!$F$5:$F$38,MATCH($A9,'Ingredient Database'!$A$5:$A$38,0))*$C9,"check name") -> 0.299 | H9: =IFERROR(INDEX('Ingredient Database'!$G$5:$G$38,MATCH($A9,'Ingredient Database'!$A$5:$A$38,0))*$C9,"check name") -> 0.7797 | I9: =IFERROR(INDEX('Ingredient Database'!$H$5:$H$38,MATCH($A9,'Ingredient Database'!$A$5:$A$38,0))*$C9,"check name") -> 0.2714 | J9: =IFERROR(INDEX('Ingredient Database'!$I$5:$I$38,MATCH($A9,'Ingredient Database'!$A$5:$A$38,0))*$C9,"check name") -> 14.536 | K9: =IFERROR(INDEX('Ingredient Database'!$J$5:$J$38,MATCH($A9,'Ingredient Database'!$A$5:$A$38,0))*$C9,"check name") -> 5.957 | L9: =IFERROR(INDEX('Ingredient Database'!$K$5:$K$38,MATCH($A9,'Ingredient Database'!$A$5:$A$38,0))*$C9,"check name") -> 23.46 | M9: =IFERROR(INDEX('Ingredient Database'!$L$5:$L$38,MATCH($A9,'Ingredient Database'!$A$5:$A$38,0))*$C9,"check name") -> 0.0529 | N9: =IFERROR(INDEX('Ingredient Database'!$M$5:$M$38,MATCH($A9,'Ingredient Database'!$A$5:$A$38,0))*$C9,"check name") -> 0.138 | O9: =IFERROR(INDEX('Ingredient Database'!$N$5:$N$38,MATCH($A9,'Ingredient Database'!$A$5:$A$38,0))*$C9,"check name") -> 0 | P9: =IFERROR(INDEX('Ingredient Database'!$O$5:$O$38,MATCH($A9,'Ingredient Database'!$A$5:$A$38,0))*$C9,"check name") -> 0
A10: Maple syrup | B10: 79 g (1/4 cup) | C10: 0.79 | D10: =IFERROR(INDEX('Ingredient Database'!$C$5:$C$38,MATCH($A10,'Ingredient Database'!$A$5:$A$38,0))*$C10,"check name") -> 205.4 | E10: =IFERROR(INDEX('Ingredient Database'!$D$5:$D$38,MATCH($A10,'Ingredient Database'!$A$5:$A$38,0))*$C10,"check name") -> 0 | F10: =IFERROR(INDEX('Ingredient Database'!$E$5:$E$38,MATCH($A10,'Ingredient Database'!$A$5:$A$38,0))*$C10,"check name") -> 52.93 | G10: =IFERROR(INDEX('Ingredient Database'!$F$5:$F$38,MATCH($A10,'Ingredient Database'!$A$5:$A$38,0))*$C10,"check name") -> 0 | H10: =IFERROR(INDEX('Ingredient Database'!$G$5:$G$38,MATCH($A10,'Ingredient Database'!$A$5:$A$38,0))*$C10,"check name") -> 0 | I10: =IFERROR(INDEX('Ingredient Database'!$H$5:$H$38,MATCH($A10,'Ingredient Database'!$A$5:$A$38,0))*$C10,"check name") -> 0.0869 | J10: =IFERROR(INDEX('Ingredient Database'!$I$5:$I$38,MATCH($A10,'Ingredient Database'!$A$5:$A$38,0))*$C10,"check name") -> 80.58 | K10: =IFERROR(INDEX('Ingredient Database'!$J$5:$J$38,MATCH($A10,'Ingredient Database'!$A$5:$A$38,0))*$C10,"check name") -> 16.59 | L10: =IFERROR(INDEX('Ingredient Database'!$K$5:$K$38,MATCH($A10,'Ingredient Database'!$A$5:$A$38,0))*$C10,"check name") -> 167.48 | M10: =IFERROR(INDEX('Ingredient Database'!$L$5:$L$38,MATCH($A10,'Ingredient Database'!$A$5:$A$38,0))*$C10,"check name") -> 1.185 | N10: =IFERROR(INDEX('Ingredient Database'!$M$5:$M$38,MATCH($A10,'Ingredient Database'!$A$5:$A$38,0))*$C10,"check name") -> 0 | O10: =IFERROR(INDEX('Ingredient Database'!$N$5:$N$38,MATCH($A10,'Ingredient Database'!$A$5:$A$38,0))*$C10,"check name") -> 0 | P10: =IFERROR(INDEX('Ingredient Database'!$O$5:$O$38,MATCH($A10,'Ingredient Database'!$A$5:$A$38,0))*$C10,"check name") -> 0
A11: Coconut oil | B11: 73 g (1/3 cup) | C11: 0.73 | D11: =IFERROR(INDEX('Ingredient Database'!$C$5:$C$38,MATCH($A11,'Ingredient Database'!$A$5:$A$38,0))*$C11,"check name") -> 629.26 | E11: =IFERROR(INDEX('Ingredient Database'!$D$5:$D$38,MATCH($A11,'Ingredient Database'!$A$5:$A$38,0))*$C11,"check name") -> 0 | F11: =IFERROR(INDEX('Ingredient Database'!$E$5:$E$38,MATCH($A11,'Ingredient Database'!$A$5:$A$38,0))*$C11,"check name") -> 0 | G11: =IFERROR(INDEX('Ingredient Database'!$F$5:$F$38,MATCH($A11,'Ingredient Database'!$A$5:$A$38,0))*$C11,"check name") -> 73 | H11: =IFERROR(INDEX('Ingredient Database'!$G$5:$G$38,MATCH($A11,'Ingredient Database'!$A$5:$A$38,0))*$C11,"check name") -> 0 | I11: =IFERROR(INDEX('Ingredient Database'!$H$5:$H$38,MATCH($A11,'Ingredient Database'!$A$5:$A$38,0))*$C11,"check name") -> 0 | J11: =IFERROR(INDEX('Ingredient Database'!$I$5:$I$38,MATCH($A11,'Ingredient Database'!$A$5:$A$38,0))*$C11,"check name") -> 0 | K11: =IFERROR(INDEX('Ingredient Database'!$J$5:$J$38,MATCH($A11,'Ingredient Database'!$A$5:$A$38,0))*$C11,"check name") -> 0 | L11: =IFERROR(INDEX('Ingredient Database'!$K$5:$K$38,MATCH($A11,'Ingredient Database'!$A$5:$A$38,0))*$C11,"check name") -> 0 | M11: =IFERROR(INDEX('Ingredient Database'!$L$5:$L$38,MATCH($A11,'Ingredient Database'!$A$5:$A$38,0))*$C11,"check name") -> 0 | N11: =IFERROR(INDEX('Ingredient Database'!$M$5:$M$38,MATCH($A11,'Ingredient Database'!$A$5:$A$38,0))*$C11,"check name") -> 0 | O11: =IFERROR(INDEX('Ingredient Database'!$N$5:$N$38,MATCH($A11,'Ingredient Database'!$A$5:$A$38,0))*$C11,"check name") -> 0 | P11: =IFERROR(INDEX('Ingredient Database'!$O$5:$O$38,MATCH($A11,'Ingredient Database'!$A$5:$A$38,0))*$C11,"check name") -> 0
